<?xml version="1.0" ?>
<robot name="robot_arm" xmlns:xacro="http://www.ros.org/wiki/xacro">

<xacro:include filename="$(find robot_arm_description)/urdf/materials.xacro" />
<xacro:include filename="$(find robot_arm_description)/urdf/robot_arm.trans" />
<xacro:include filename="$(find robot_arm_description)/urdf/robot_arm.gazebo" />
<link name="base_link">
  <inertial>
    <origin rpy="0 0 0" xyz="0.0035168152143238885 -1.666668598250173e-05 0.028012530522048572"/>
    <mass value="2.185751701331884"/>
    <inertia ixx="0.001335" ixy="1e-06" ixz="1.9e-05" iyy="0.001636" iyz="-0.0" izz="0.001824"/>
  </inertial>
  <visual>
    <origin rpy="0 0 0" xyz="0 0 0"/>
    <geometry>
      <mesh filename="package://robot_arm_description/meshes/base_link.stl" scale="0.001 0.001 0.001"/>
    </geometry>
    <material name="silver"/>
  </visual>
  <collision>
    <origin rpy="0 0 0" xyz="0 0 0"/>
    <geometry>
      <mesh filename="package://robot_arm_description/meshes/base_link.stl" scale="0.001 0.001 0.001"/>
    </geometry>
  </collision>
</link>

<link name="revolve_base_1">
  <inertial>
    <origin rpy="0 0 0" xyz="0.0017897130322263764 0.00042170936534176653 0.026773254955700786"/>
    <mass value="1.2509746408878526"/>
    <inertia ixx="0.001" ixy="-8.7e-05" ixz="-8.6e-05" iyy="0.001251" iyz="-2.2e-05" izz="0.000961"/>
  </inertial>
  <visual>
    <origin rpy="0 0 0" xyz="-0.0 -0.0 -0.057"/>
    <geometry>
      <mesh filename="package://robot_arm_description/meshes/revolve_base_1.stl" scale="0.001 0.001 0.001"/>
    </geometry>
    <material name="silver"/>
  </visual>
  <collision>
    <origin rpy="0 0 0" xyz="-0.0 -0.0 -0.057"/>
    <geometry>
      <mesh filename="package://robot_arm_description/meshes/revolve_base_1.stl" scale="0.001 0.001 0.001"/>
    </geometry>
  </collision>
</link>

<link name="wrist_1">
  <inertial>
    <origin rpy="0 0 0" xyz="0.003065372604041359 -0.009864308349769313 0.009328175760730806"/>
    <mass value="0.28923335599926986"/>
    <inertia ixx="0.000107" ixy="6e-06" ixz="2e-06" iyy="8.9e-05" iyz="-6e-06" izz="9.8e-05"/>
  </inertial>
  <visual>
    <origin rpy="0 0 0" xyz="-0.021049 0.172921 -0.291615"/>
    <geometry>
      <mesh filename="package://robot_arm_description/meshes/wrist_1.stl" scale="0.001 0.001 0.001"/>
    </geometry>
    <material name="silver"/>
  </visual>
  <collision>
    <origin rpy="0 0 0" xyz="-0.021049 0.172921 -0.291615"/>
    <geometry>
      <mesh filename="package://robot_arm_description/meshes/wrist_1.stl" scale="0.001 0.001 0.001"/>
    </geometry>
  </collision>
</link>

<link name="arm_1_1">
  <inertial>
    <origin rpy="0 0 0" xyz="0.009678350788639366 -0.031024087232192774 0.04217806875038599"/>
    <mass value="2.0651308300124485"/>
    <inertia ixx="0.004269" ixy="0.00044" ixz="-0.000552" iyy="0.003014" iyz="0.00175" izz="0.002047"/>
  </inertial>
  <visual>
    <origin rpy="0 0 0" xyz="0.00051 0.000511 -0.12"/>
    <geometry>
      <mesh filename="package://robot_arm_description/meshes/arm_1_1.stl" scale="0.001 0.001 0.001"/>
    </geometry>
    <material name="silver"/>
  </visual>
  <collision>
    <origin rpy="0 0 0" xyz="0.00051 0.000511 -0.12"/>
    <geometry>
      <mesh filename="package://robot_arm_description/meshes/arm_1_1.stl" scale="0.001 0.001 0.001"/>
    </geometry>
  </collision>
</link>

<link name="arm_2_1">
  <inertial>
    <origin rpy="0 0 0" xyz="-0.0001461436327167753 -0.03941528581653511 0.02811698241626634"/>
    <mass value="0.7899537328202426"/>
    <inertia ixx="0.001183" ixy="0.000209" ixz="-0.000163" iyy="0.000589" iyz="0.000517" izz="0.000801"/>
  </inertial>
  <visual>
    <origin rpy="0 0 0" xyz="-0.003105 0.076796 -0.214544"/>
    <geometry>
      <mesh filename="package://robot_arm_description/meshes/arm_2_1.stl" scale="0.001 0.001 0.001"/>
    </geometry>
    <material name="silver"/>
  </visual>
  <collision>
    <origin rpy="0 0 0" xyz="-0.003105 0.076796 -0.214544"/>
    <geometry>
      <mesh filename="package://robot_arm_description/meshes/arm_2_1.stl" scale="0.001 0.001 0.001"/>
    </geometry>
  </collision>
</link>

<link name="hand_mount_1">
  <inertial>
    <origin rpy="0 0 0" xyz="0.005052870434540755 0.0014531875127082317 -8.069353456929829e-05"/>
    <mass value="0.34294901678601714"/>
    <inertia ixx="5.8e-05" ixy="-1.7e-05" ixz="-0.0" iyy="0.000114" iyz="4e-06" izz="0.000118"/>
  </inertial>
  <visual>
    <origin rpy="0 0 0" xyz="-0.029678 0.200228 -0.32096"/>
    <geometry>
      <mesh filename="package://robot_arm_description/meshes/hand_mount_1.stl" scale="0.001 0.001 0.001"/>
    </geometry>
    <material name="silver"/>
  </visual>
  <collision>
    <origin rpy="0 0 0" xyz="-0.029678 0.200228 -0.32096"/>
    <geometry>
      <mesh filename="package://robot_arm_description/meshes/hand_mount_1.stl" scale="0.001 0.001 0.001"/>
    </geometry>
  </collision>
</link>

<joint name="base_rev" type="continuous">
  <origin rpy="0 0 0" xyz="0.0 0.0 0.057"/>
  <parent link="base_link"/>
  <child link="revolve_base_1"/>
  <axis xyz="0.0 0.0 1.0"/>
</joint>

<joint name="Wrist_joint" type="continuous">
  <origin rpy="0 0 0" xyz="0.017944 -0.096125 0.077071"/>
  <parent link="arm_2_1"/>
  <child link="wrist_1"/>
  <axis xyz="-0.212709 0.674355 -0.707107"/>
</joint>

<joint name="Shoulder_joint" type="continuous">
  <origin rpy="0 0 0" xyz="-0.00051 -0.000511 0.063"/>
  <parent link="revolve_base_1"/>
  <child link="arm_1_1"/>
  <axis xyz="-0.953682 -0.300816 0.0"/>
</joint>

<joint name="Elbow_joint" type="continuous">
  <origin rpy="0 0 0" xyz="0.003615 -0.076285 0.094544"/>
  <parent link="arm_1_1"/>
  <child link="arm_2_1"/>
  <axis xyz="-0.953682 -0.300816 0.0"/>
</joint>

<joint name="Hand_rev" type="continuous">
  <origin rpy="0 0 0" xyz="0.008629 -0.027307 0.029345"/>
  <parent link="wrist_1"/>
  <child link="hand_mount_1"/>
  <axis xyz="0.184245 -0.683005 -0.706794"/>
</joint>

</robot>
